Workbook

Sheet Assumption
B1: 센텀C부지 복합개발사업 재무모델 | I1: 입력값 | J1: 파란 글씨 = 입력(하드코딩)
B2: Assumption (단위: 백만원) | I2: 수식 | J2: 검정 = 계산 수식
C3: =IF(ABS(CF!$C$159)<1,"OK","Error") -> OK | D3: =IF(SUMPRODUCT(ABS($F$544:$F$553))<1,"OK","Run Macro") -> OK | E3: =IF(MIN(CF!$E$159:$EF$159)>-0.5,"OK","Shortage") -> OK | F3: =IF(SUM(CF!$E$153:$EF$153)-SUM(CF!$E$116:$EF$116)<1,"OK","PF한도부족") -> OK | I3: 연결 | J3: 초록 = CF 시트 연결
C4: Balance Check | D4: Macro Check | E4: Shortage Check | F4: Cash Check | I4: Macro | J4: 노랑 = Macro Paste 값(순환참조 차단)
A6: 프로젝트 일정 (계획)
B8: 리츠설립일 | D8: Date | E8: 46112
B9: 매매계약체결 준비기간 | D9: Months | E9: 3
B10: 토지매매계약체결일 | D10: Date | E10: =EOMONTH($E$8,$E$9) -> 46203
B11: 인허가 준비기간 | D11: Months | E11: 14
B12: 인허가 완료일 | D12: Date | E12: =EOMONTH($E$10,$E$11) -> 46630
B13: 공사준비기간 | D13: Months | E13: 1
B14: 착공일 | D14: Date | E14: =EOMONTH($E$12,$E$13) -> 46660
B15: 공사기간 | D15: Months | E15: 42
B16: 준공일 | D16: Date | E16: =EOMONTH($E$14,$E$15-1) -> 47907
B17: 운영준비기간 | D17: Months | E17: 1
B18: 운영개시일 | D18: Date | E18: =EOMONTH($E$16,$E$17) -> 47938
B19: 운영기간 | D19: Months | E19: 60
B20: 운영종료일 | D20: Date | E20: =EOMONTH($E$18,$E$19-1) -> 49734
B21: 처분준비기간 | D21: Months | E21: 0
B22: 처분일 | D22: Date | E22: =EOMONTH($E$20,$E$21) -> 49734
B23: 청산준비기간 | D23: Months | E23: 3
B24: 리츠청산일 | D24: Date | E24: =EOMONTH($E$22,$E$23) -> 49826
B25: 개발기간(설립~준공) | D25: Years | E25: =((YEAR($E$16)-YEAR($E$8))*12+MONTH($E$16)-MONTH($E$8)+1)/12 -> 5
B26: 리츠운용기간(운영개시~청산) | D26: Years | E26: =((YEAR($E$24)-YEAR($E$18))*12+MONTH($E$24)-MONTH($E$18)+1)/12 -> 5.25
A28: Results
B30: IRR On Equity (보통주) | E30: =CF!$C$171 -> 0.20392787
B31: IRR On Equity (우선주) | E31: =CF!$C$172 -> 0.05
B32: IRR On Equity (전체) | E32: =CF!$C$173 -> 0.12111635
A34: 사업개요
B36: (1) 사 업 명 | D36: 센텀C부지 복합개발사업
B37: (2) 대 지 위 치 | D37: 부산광역시 해운대 우동 1492
B38: (3) 지 역 지 구 | D38: 중심상업지역/지구단위계획구역
B39: (4) 용 도 | D39: 관광숙박시설(호텔, 콘도), 노유자시설(시니어레지던스), 문화집회시설(공연장 등), 판매시설
B40: (5) 건축연면적 | E40: 평 환산계수 | F40: 0.3025
B42: 연면적 | C42: 지상연면적 | D42: 178919.43 | E42: =$D$42*$F$40 -> 54123.128
C43: 지하연면적 | D43: 91531.54 | E43: =$D$43*$F$40 -> 27688.291
C44: 전체연면적 | D44: =$D$42+$D$43 -> 270450.97 | E44: =$D$44*$F$40 -> 81811.418 | F44: =ABS($D$44-$C$56)<1 -> TRUE | G44: =ABS($D$44*$F$40-$C$55)<1 -> TRUE
B46: 용도별 연면적 | C46: 시니어 레지던스 | D46: =SUMIF($D$53:$W$53,"시니어 레지던스",$D$56:$W$56) -> 76060.08 | E46: =SUMIF($D$53:$W$53,"시니어 레지던스",$D$55:$W$55) -> 23008.174
C47: 레지던스 | D47: =SUMIF($D$53:$W$53,"레지던스",$D$56:$W$56) -> 44693.91 | E47: =SUMIF($D$53:$W$53,"레지던스",$D$55:$W$55) -> 13519.908
C48: 호텔 | D48: =SUMIF($D$53:$W$53,"호텔",$D$56:$W$56) -> 70374.3 | E48: =SUMIF($D$53:$W$53,"호텔",$D$55:$W$55) -> 21288.226
...

Sheet CF
A1: 월별 현금흐름 (CF) — 단위: 백만원
A3: ※ 월말 기준. 모든 입력은 Assumption 시트 연결. C열 = 기간 합계(잔액행은 최대값/최종값, IRR행은 연환산 IRR)
A5: 구분 | B5: 단위 | C5: 합계
A6: 월말일자 | E6: =EOMONTH(Assumption!$E$8,0) -> 46112 | F6: =EOMONTH(E6,1) -> 46142 | G6: =EOMONTH(F6,1) -> 46173 | H6: =EOMONTH(G6,1) -> 46203 | I6: =EOMONTH(H6,1) -> 46234 | J6: =EOMONTH(I6,1) -> 46265 | K6: =EOMONTH(J6,1) -> 46295 | L6: =EOMONTH(K6,1) -> 46326 | M6: =EOMONTH(L6,1) -> 46356 | ... EF6: =EOMONTH(EE6,1) -> 50099
A7: 연도 | E7: =YEAR(E6) -> 2026 | F7: =YEAR(F6) -> 2026 | G7: =YEAR(G6) -> 2026 | H7: =YEAR(H6) -> 2026 | I7: =YEAR(I6) -> 2026 | J7: =YEAR(J6) -> 2026 | K7: =YEAR(K6) -> 2026 | L7: =YEAR(L6) -> 2026 | ... EF7: =YEAR(EF6) -> 2037
A8: 월차 | E8: =1 -> 1 | F8: =E8+1 -> 2 | G8: =F8+1 -> 3 | H8: =G8+1 -> 4 | I8: =H8+1 -> 5 | J8: =I8+1 -> 6 | K8: =J8+1 -> 7 | L8: =K8+1 -> 8 | M8: =L8+1 -> 9 | ... EF8: =EE8+1 -> 132
A9: 모델기간 Flag | E9: =IF(E6<=Assumption!$E$24,1,0) -> 1 | F9: =IF(F6<=Assumption!$E$24,1,0) -> 1 | G9: =IF(G6<=Assumption!$E$24,1,0) -> 1 | H9: =IF(H6<=Assumption!$E$24,1,0) -> 1 | I9: =IF(I6<=Assumption!$E$24,1,0) -> 1 | J9: =IF(J6<=Assumption!$E$24,1,0) -> 1 | K9: =IF(K6<=Assumption!$E$24,1,0) -> 1 | L9: =IF(L6<=Assumption!$E$24,1,0) -> 1 | ... EF9: =IF(EF6<=Assumption!$E$24,1,0) -> 0
A10: 개발기간 Flag(설립~준공) | E10: =IF(E6<=Assumption!$E$16,1,0) -> 1 | F10: =IF(F6<=Assumption!$E$16,1,0) -> 1 | G10: =IF(G6<=Assumption!$E$16,1,0) -> 1 | H10: =IF(H6<=Assumption!$E$16,1,0) -> 1 | I10: =IF(I6<=Assumption!$E$16,1,0) -> 1 | J10: =IF(J6<=Assumption!$E$16,1,0) -> 1 | K10: =IF(K6<=Assumption!$E$16,1,0) -> 1 | L10: =IF(L6<=Assumption!$E$16,1,0) -> 1 | ... EF10: =IF(EF6<=Assumption!$E$16,1,0) -> 0
A11: 공사기간 Flag | E11: =IF(AND(E6>=Assumption!$E$14,E6<=Assumption!$E$16),1,0) -> 0 | F11: =IF(AND(F6>=Assumption!$E$14,F6<=Assumption!$E$16),1,0) -> 0 | G11: =IF(AND(G6>=Assumption!$E$14,G6<=Assumption!$E$16),1,0) -> 0 | H11: =IF(AND(H6>=Assumption!$E$14,H6<=Assumption!$E$16),1,0) -> 0 | I11: =IF(AND(I6>=Assumption!$E$14,I6<=Assumption!$E$16),1,0) -> 0 | J11: =IF(AND(J6>=Assumption!$E$14,J6<=Assumption!$E$16),1,0) -> 0 | K11: =IF(AND(K6>=Assumption!$E$14,K6<=Assumption!$E$16),1,0) -> 0 | L11: =IF(AND(L6>=Assumption!$E$14,L6<=Assumption!$E$16),1,0) -> 0 | ... EF11: =IF(AND(EF6>=Assumption!$E$14,EF6<=Assumption!$E$16),1,0) -> 0
A12: 공사 월차 | E12: =IF(E11=1,(YEAR(E6)-YEAR(Assumption!$E$14))*12+MONTH(E6)-MONTH(Assumption!$E$14)+1,0) -> 0 | F12: =IF(F11=1,(YEAR(F6)-YEAR(Assumption!$E$14))*12+MONTH(F6)-MONTH(Assumption!$E$14)+1,0) -> 0 | G12: =IF(G11=1,(YEAR(G6)-YEAR(Assumption!$E$14))*12+MONTH(G6)-MONTH(Assumption!$E$14)+1,0) -> 0 | H12: =IF(H11=1,(YEAR(H6)-YEAR(Assumption!$E$14))*12+MONTH(H6)-MONTH(Assumption!$E$14)+1,0) -> 0 | I12: =IF(I11=1,(YEAR(I6)-YEAR(Assumption!$E$14))*12+MONTH(I6)-MONTH(Assumption!$E$14)+1,0) -> 0 | J12: =IF(J11=1,(YEAR(J6)-YEAR(Assumption!$E$14))*12+MONTH(J6)-MONTH(Assumption!$E$14)+1,0) -> 0 | K12: =IF(K11=1,(YEAR(K6)-YEAR(Assumption!$E$14))*12+MONTH(K6)-MONTH(Assumption!$E$14)+1,0) -> 0 | L12: =IF(L11=1,(YEAR(L6)-YEAR(Assumption!$E$14))*12+MONTH(L6)-MONTH(Assumption!$E$14)+1,0) -> 0 | ... EF12: =IF(EF11=1,(YEAR(EF6)-YEAR(Assumption!$E$14))*12+MONTH(EF6)-MONTH(Assumption!$E$14)+1,0) -> 0
A13: S-curve 집행률 | B13: % | C13: =SUM(E13:EF13) -> 1 | E13: =IF(E12>0,(COS(PI()*(E12-1)/Assumption!$E$15)-COS(PI()*E12/Assumption!$E$15))/2,0) -> 0 | F13: =IF(F12>0,(COS(PI()*(F12-1)/Assumption!$E$15)-COS(PI()*F12/Assumption!$E$15))/2,0) -> 0 | G13: =IF(G12>0,(COS(PI()*(G12-1)/Assumption!$E$15)-COS(PI()*G12/Assumption!$E$15))/2,0) -> 0 | H13: =IF(H12>0,(COS(PI()*(H12-1)/Assumption!$E$15)-COS(PI()*H12/Assumption!$E$15))/2,0) -> 0 | I13: =IF(I12>0,(COS(PI()*(I12-1)/Assumption!$E$15)-COS(PI()*I12/Assumption!$E$15))/2,0) -> 0 | J13: =IF(J12>0,(COS(PI()*(J12-1)/Assumption!$E$15)-COS(PI()*J12/Assumption!$E$15))/2,0) -> 0 | K13: =IF(K12>0,(COS(PI()*(K12-1)/Assumption!$E$15)-COS(PI()*K12/Assumption!$E$15))/2,0) -> 0 | L13: =IF(L12>0,(COS(PI()*(L12-1)/Assumption!$E$15)-COS(PI()*L12/Assumption!$E$15))/2,0) -> 0 | ... EF13: =IF(EF12>0,(COS(PI()*(EF12-1)/Assumption!$E$15)-COS(PI()*EF12/Assumption!$E$15))/2,0) -> 0
A14: 운영기간 Flag | E14: =IF(AND(E6>=Assumption!$E$18,E6<=Assumption!$E$20),1,0) -> 0 | F14: =IF(AND(F6>=Assumption!$E$18,F6<=Assumption!$E$20),1,0) -> 0 | G14: =IF(AND(G6>=Assumption!$E$18,G6<=Assumption!$E$20),1,0) -> 0 | H14: =IF(AND(H6>=Assumption!$E$18,H6<=Assumption!$E$20),1,0) -> 0 | I14: =IF(AND(I6>=Assumption!$E$18,I6<=Assumption!$E$20),1,0) -> 0 | J14: =IF(AND(J6>=Assumption!$E$18,J6<=Assumption!$E$20),1,0) -> 0 | K14: =IF(AND(K6>=Assumption!$E$18,K6<=Assumption!$E$20),1,0) -> 0 | L14: =IF(AND(L6>=Assumption!$E$18,L6<=Assumption!$E$20),1,0) -> 0 | ... EF14: =IF(AND(EF6>=Assumption!$E$18,EF6<=Assumption!$E$20),1,0) -> 0
A15: 운영 월차 | E15: =IF(E14=1,(YEAR(E6)-YEAR(Assumption!$E$18))*12+MONTH(E6)-MONTH(Assumption!$E$18)+1,0) -> 0 | F15: =IF(F14=1,(YEAR(F6)-YEAR(Assumption!$E$18))*12+MONTH(F6)-MONTH(Assumption!$E$18)+1,0) -> 0 | G15: =IF(G14=1,(YEAR(G6)-YEAR(Assumption!$E$18))*12+MONTH(G6)-MONTH(Assumption!$E$18)+1,0) -> 0 | H15: =IF(H14=1,(YEAR(H6)-YEAR(Assumption!$E$18))*12+MONTH(H6)-MONTH(Assumption!$E$18)+1,0) -> 0 | I15: =IF(I14=1,(YEAR(I6)-YEAR(Assumption!$E$18))*12+MONTH(I6)-MONTH(Assumption!$E$18)+1,0) -> 0 | J15: =IF(J14=1,(YEAR(J6)-YEAR(Assumption!$E$18))*12+MONTH(J6)-MONTH(Assumption!$E$18)+1,0) -> 0 | K15: =IF(K14=1,(YEAR(K6)-YEAR(Assumption!$E$18))*12+MONTH(K6)-MONTH(Assumption!$E$18)+1,0) -> 0 | L15: =IF(L14=1,(YEAR(L6)-YEAR(Assumption!$E$18))*12+MONTH(L6)-MONTH(Assumption!$E$18)+1,0) -> 0 | ... EF15: =IF(EF14=1,(YEAR(EF6)-YEAR(Assumption!$E$18))*12+MONTH(EF6)-MONTH(Assumption!$E$18)+1,0) -> 0
A16: 운영 연차 | E16: =IF(E15>0,INT((E15-1)/12)+1,0) -> 0 | F16: =IF(F15>0,INT((F15-1)/12)+1,0) -> 0 | G16: =IF(G15>0,INT((G15-1)/12)+1,0) -> 0 | H16: =IF(H15>0,INT((H15-1)/12)+1,0) -> 0 | I16: =IF(I15>0,INT((I15-1)/12)+1,0) -> 0 | J16: =IF(J15>0,INT((J15-1)/12)+1,0) -> 0 | K16: =IF(K15>0,INT((K15-1)/12)+1,0) -> 0 | L16: =IF(L15>0,INT((L15-1)/12)+1,0) -> 0 | ... EF16: =IF(EF15>0,INT((EF15-1)/12)+1,0) -> 0
A17: 리츠운용기간 Flag(운영개시~청산) | E17: =IF(AND(E6>=Assumption!$E$18,E6<=Assumption!$E$24),1,0) -> 0 | F17: =IF(AND(F6>=Assumption!$E$18,F6<=Assumption!$E$24),1,0) -> 0 | G17: =IF(AND(G6>=Assumption!$E$18,G6<=Assumption!$E$24),1,0) -> 0 | H17: =IF(AND(H6>=Assumption!$E$18,H6<=Assumption!$E$24),1,0) -> 0 | I17: =IF(AND(I6>=Assumption!$E$18,I6<=Assumption!$E$24),1,0) -> 0 | J17: =IF(AND(J6>=Assumption!$E$18,J6<=Assumption!$E$24),1,0) -> 0 | K17: =IF(AND(K6>=Assumption!$E$18,K6<=Assumption!$E$24),1,0) -> 0 | L17: =IF(AND(L6>=Assumption!$E$18,L6<=Assumption!$E$24),1,0) -> 0 | ... EF17: =IF(AND(EF6>=Assumption!$E$18,EF6<=Assumption!$E$24),1,0) -> 0
A18: 일수 | B18: 일 | E18: =DAY(E6) -> 31 | F18: =DAY(F6) -> 30 | G18: =DAY(G6) -> 31 | H18: =DAY(H6) -> 30 | I18: =DAY(I6) -> 31 | J18: =DAY(J6) -> 31 | K18: =DAY(K6) -> 30 | L18: =DAY(L6) -> 31 | ... EF18: =DAY(EF6) -> 28
A20: 운영수입
A21: 시니어 레지던스 이용료·임대료 | B21: 백만원 | C21: =SUM(E21:EF21) -> 97278.541 | E21: =(E14=1)*Assumption!$E$82*CHOOSE(MIN(MAX(E16,1),3),Assumption!$E$90,Assumption!$E$91,Assumption!$E$92)*(Assumption!$E$86+Assumption!$E$85)/1000*(1+Assumption!$E$87)^INT((E15-1)/Assumption!$E$88) -> 0 | F21: =(F14=1)*Assumption!$E$82*CHOOSE(MIN(MAX(F16,1),3),Assumption!$E$90,Assumption!$E$91,Assumption!$E$92)*(Assumption!$E$86+Assumption!$E$85)/1000*(1+Assumption!$E$87)^INT((F15-1)/Assumption!$E$88) -> 0 | G21: =(G14=1)*Assumption!$E$82*CHOOSE(MIN(MAX(G16,1),3),Assumption!$E$90,Assumption!$E$91,Assumption!$E$92)*(Assumption!$E$86+Assumption!$E$85)/1000*(1+Assumption!$E$87)^INT((G15-1)/Assumption!$E$88) -> 0 | H21: =(H14=1)*Assumption!$E$82*CHOOSE(MIN(MAX(H16,1),3),Assumption!$E$90,Assumption!$E$91,Assumption!$E$92)*(Assumption!$E$86+Assumption!$E$85)/1000*(1+Assumption!$E$87)^INT((H15-1)/Assumption!$E$88) -> 0 | I21: =(I14=1)*Assumption!$E$82*CHOOSE(MIN(MAX(I16,1),3),Assumption!$E$90,Assumption!$E$91,Assumption!$E$92)*(Assumption!$E$86+Assumption!$E$85)/1000*(1+Assumption!$E$87)^INT((I15-1)/Assumption!$E$88) -> 0 | J21: =(J14=1)*Assumption!$E$82*CHOOSE(MIN(MAX(J16,1),3),Assumption!$E$90,Assumption!$E$91,Assumption!$E$92)*(Assumption!$E$86+Assumption!$E$85)/1000*(1+Assumption!$E$87)^INT((J15-1)/Assumption!$E$88) -> 0 | K21: =(K14=1)*Assumption!$E$82*CHOOSE(MIN(MAX(K16,1),3),Assumption!$E$90,Assumption!$E$91,Assumption!$E$92)*(Assumption!$E$86+Assumption!$E$85)/1000*(1+Assumption!$E$87)^INT((K15-1)/Assumption!$E$88) -> 0 | L21: =(L14=1)*Assumption!$E$82*CHOOSE(MIN(MAX(L16,1),3),Assumption!$E$90,Assumption!$E$91,Assumption!$E$92)*(Assumption!$E$86+Assumption!$E$85)/1000*(1+Assumption!$E$87)^INT((L15-1)/Assumption!$E$88) -> 0 | ... EF21: =(EF14=1)*Assumption!$E$82*CHOOSE(MIN(MAX(EF16,1),3),Assumption!$E$90,Assumption!$E$91,Assumption!$E$92)*(Assumption!$E$86+Assumption!$E$85)/1000*(1+Assumption!$E$87)^INT((EF15-1)/Assumption!$E$88) -> 0
A22: 시니어 추가수입(세대관리비 등) | B22: 백만원 | C22: =SUM(E22:EF22) -> 14591.781 | E22: =E21*Assumption!$E$93 -> 0 | F22: =F21*Assumption!$E$93 -> 0 | G22: =G21*Assumption!$E$93 -> 0 | H22: =H21*Assumption!$E$93 -> 0 | I22: =I21*Assumption!$E$93 -> 0 | J22: =J21*Assumption!$E$93 -> 0 | K22: =K21*Assumption!$E$93 -> 0 | L22: =L21*Assumption!$E$93 -> 0 | ... EF22: =EF21*Assumption!$E$93 -> 0
A23: 시니어 부대시설 임대료 | B23: 백만원 | C23: =SUM(E23:EF23) -> 9128.7441 | E23: =(E14=1)*Assumption!$E$101*Assumption!$E$102/1000*(1+Assumption!$E$104)^INT((E15-1)/Assumption!$E$105) -> 0 | F23: =(F14=1)*Assumption!$E$101*Assumption!$E$102/1000*(1+Assumption!$E$104)^INT((F15-1)/Assumption!$E$105) -> 0 | G23: =(G14=1)*Assumption!$E$101*Assumption!$E$102/1000*(1+Assumption!$E$104)^INT((G15-1)/Assumption!$E$105) -> 0 | H23: =(H14=1)*Assumption!$E$101*Assumption!$E$102/1000*(1+Assumption!$E$104)^INT((H15-1)/Assumption!$E$105) -> 0 | I23: =(I14=1)*Assumption!$E$101*Assumption!$E$102/1000*(1+Assumption!$E$104)^INT((I15-1)/Assumption!$E$105) -> 0 | J23: =(J14=1)*Assumption!$E$101*Assumption!$E$102/1000*(1+Assumption!$E$104)^INT((J15-1)/Assumption!$E$105) -> 0 | K23: =(K14=1)*Assumption!$E$101*Assumption!$E$102/1000*(1+Assumption!$E$104)^INT((K15-1)/Assumption!$E$105) -> 0 | L23: =(L14=1)*Assumption!$E$101*Assumption!$E$102/1000*(1+Assumption!$E$104)^INT((L15-1)/Assumption!$E$105) -> 0 | ... EF23: =(EF14=1)*Assumption!$E$101*Assumption!$E$102/1000*(1+Assumption!$E$104)^INT((EF15-1)/Assumption!$E$105) -> 0
A24: 레지던스 객실매출 | B24: 백만원 | C24: =SUM(E24:EF24) -> 97070.53 | E24: =(E14=1)*Assumption!$G$115*CHOOSE(MIN(MAX(E16,1),3),Assumption!$E$122,Assumption!$E$123,Assumption!$E$124)*E18/1000000*(1+Assumption!$E$118)^(MAX(E16,1)-1) -> 0 | F24: =(F14=1)*Assumption!$G$115*CHOOSE(MIN(MAX(F16,1),3),Assumption!$E$122,Assumption!$E$123,Assumption!$E$124)*F18/1000000*(1+Assumption!$E$118)^(MAX(F16,1)-1) -> 0 | G24: =(G14=1)*Assumption!$G$115*CHOOSE(MIN(MAX(G16,1),3),Assumption!$E$122,Assumption!$E$123,Assumption!$E$124)*G18/1000000*(1+Assumption!$E$118)^(MAX(G16,1)-1) -> 0 | H24: =(H14=1)*Assumption!$G$115*CHOOSE(MIN(MAX(H16,1),3),Assumption!$E$122,Assumption!$E$123,Assumption!$E$124)*H18/1000000*(1+Assumption!$E$118)^(MAX(H16,1)-1) -> 0 | I24: =(I14=1)*Assumption!$G$115*CHOOSE(MIN(MAX(I16,1),3),Assumption!$E$122,Assumption!$E$123,Assumption!$E$124)*I18/1000000*(1+Assumption!$E$118)^(MAX(I16,1)-1) -> 0 | J24: =(J14=1)*Assumption!$G$115*CHOOSE(MIN(MAX(J16,1),3),Assumption!$E$122,Assumption!$E$123,Assumption!$E$124)*J18/1000000*(1+Assumption!$E$118)^(MAX(J16,1)-1) -> 0 | K24: =(K14=1)*Assumption!$G$115*CHOOSE(MIN(MAX(K16,1),3),Assumption!$E$122,Assumption!$E$123,Assumption!$E$124)*K18/1000000*(1+Assumption!$E$118)^(MAX(K16,1)-1) -> 0 | L24: =(L14=1)*Assumption!$G$115*CHOOSE(MIN(MAX(L16,1),3),Assumption!$E$122,Assumption!$E$123,Assumption!$E$124)*L18/1000000*(1+Assumption!$E$118)^(MAX(L16,1)-1) -> 0 | ... EF24: =(EF14=1)*Assumption!$G$115*CHOOSE(MIN(MAX(EF16,1),3),Assumption!$E$122,Assumption!$E$123,Assumption!$E$124)*EF18/1000000*(1+Assumption!$E$118)^(MAX(EF16,1)-1) -> 0
A25: 레지던스 객실외매출 | B25: 백만원 | C25: =SUM(E25:EF25) -> 64746.044 | E25: =E24*Assumption!$E$125 -> 0 | F25: =F24*Assumption!$E$125 -> 0 | G25: =G24*Assumption!$E$125 -> 0 | H25: =H24*Assumption!$E$125 -> 0 | I25: =I24*Assumption!$E$125 -> 0 | J25: =J24*Assumption!$E$125 -> 0 | K25: =K24*Assumption!$E$125 -> 0 | L25: =L24*Assumption!$E$125 -> 0 | ... EF25: =EF24*Assumption!$E$125 -> 0
A26: 레지던스 멤버전용 매출 | B26: 백만원 | C26: =SUM(E26:EF26) -> 35430.744 | E26: =E24*Assumption!$E$130 -> 0 | F26: =F24*Assumption!$E$130 -> 0 | G26: =G24*Assumption!$E$130 -> 0 | H26: =H24*Assumption!$E$130 -> 0 | I26: =I24*Assumption!$E$130 -> 0 | J26: =J24*Assumption!$E$130 -> 0 | K26: =K24*Assumption!$E$130 -> 0 | L26: =L24*Assumption!$E$130 -> 0 | ... EF26: =EF24*Assumption!$E$130 -> 0
A27: 호텔 객실매출 | B27: 백만원 | C27: =SUM(E27:EF27) -> 214271.36 | E27: =(E14=1)*Assumption!$E$134*Assumption!$E$145*CHOOSE(MIN(MAX(E16,1),3),Assumption!$E$146,Assumption!$E$147,Assumption!$E$148)*E18/1000000*(1+Assumption!$E$141)^(MAX(E16,1)-1) -> 0 | F27: =(F14=1)*Assumption!$E$134*Assumption!$E$145*CHOOSE(MIN(MAX(F16,1),3),Assumption!$E$146,Assumption!$E$147,Assumption!$E$148)*F18/1000000*(1+Assumption!$E$141)^(MAX(F16,1)-1) -> 0 | G27: =(G14=1)*Assumption!$E$134*Assumption!$E$145*CHOOSE(MIN(MAX(G16,1),3),Assumption!$E$146,Assumption!$E$147,Assumption!$E$148)*G18/1000000*(1+Assumption!$E$141)^(MAX(G16,1)-1) -> 0 | H27: =(H14=1)*Assumption!$E$134*Assumption!$E$145*CHOOSE(MIN(MAX(H16,1),3),Assumption!$E$146,Assumption!$E$147,Assumption!$E$148)*H18/1000000*(1+Assumption!$E$141)^(MAX(H16,1)-1) -> 0 | I27: =(I14=1)*Assumption!$E$134*Assumption!$E$145*CHOOSE(MIN(MAX(I16,1),3),Assumption!$E$146,Assumption!$E$147,Assumption!$E$148)*I18/1000000*(1+Assumption!$E$141)^(MAX(I16,1)-1) -> 0 | J27: =(J14=1)*Assumption!$E$134*Assumption!$E$145*CHOOSE(MIN(MAX(J16,1),3),Assumption!$E$146,Assumption!$E$147,Assumption!$E$148)*J18/1000000*(1+Assumption!$E$141)^(MAX(J16,1)-1) -> 0 | K27: =(K14=1)*Assumption!$E$134*Assumption!$E$145*CHOOSE(MIN(MAX(K16,1),3),Assumption!$E$146,Assumption!$E$147,Assumption!$E$148)*K18/1000000*(1+Assumption!$E$141)^(MAX(K16,1)-1) -> 0 | L27: =(L14=1)*Assumption!$E$134*Assumption!$E$145*CHOOSE(MIN(MAX(L16,1),3),Assumption!$E$146,Assumption!$E$147,Assumption!$E$148)*L18/1000000*(1+Assumption!$E$141)^(MAX(L16,1)-1) -> 0 | ... EF27: =(EF14=1)*Assumption!$E$134*Assumption!$E$145*CHOOSE(MIN(MAX(EF16,1),3),Assumption!$E$146,Assumption!$E$147,Assumption!$E$148)*EF18/1000000*(1+Assumption!$E$141)^(MAX(EF16,1)-1) -> 0
A28: 호텔 객실외매출(식음) | B28: 백만원 | C28: =SUM(E28:EF28) -> 96422.111 | E28: =E27*Assumption!$E$149 -> 0 | F28: =F27*Assumption!$E$149 -> 0 | G28: =G27*Assumption!$E$149 -> 0 | H28: =H27*Assumption!$E$149 -> 0 | I28: =I27*Assumption!$E$149 -> 0 | J28: =J27*Assumption!$E$149 -> 0 | K28: =K27*Assumption!$E$149 -> 0 | L28: =L27*Assumption!$E$149 -> 0 | ... EF28: =EF27*Assumption!$E$149 -> 0
A29: 호텔 객실외매출(기타) | B29: 백만원 | C29: =SUM(E29:EF29) -> 12856.281 | E29: =E27*Assumption!$E$150 -> 0 | F29: =F27*Assumption!$E$150 -> 0 | G29: =G27*Assumption!$E$150 -> 0 | H29: =H27*Assumption!$E$150 -> 0 | I29: =I27*Assumption!$E$150 -> 0 | J29: =J27*Assumption!$E$150 -> 0 | K29: =K27*Assumption!$E$150 -> 0 | L29: =L27*Assumption!$E$150 -> 0 | ... EF29: =EF27*Assumption!$E$150 -> 0
A30: 컨벤션(연회장) | B30: 백만원 | C30: =SUM(E30:EF30) -> 77137.689 | E30: =E27*Assumption!$E$155 -> 0 | F30: =F27*Assumption!$E$155 -> 0 | G30: =G27*Assumption!$E$155 -> 0 | H30: =H27*Assumption!$E$155 -> 0 | I30: =I27*Assumption!$E$155 -> 0 | J30: =J27*Assumption!$E$155 -> 0 | K30: =K27*Assumption!$E$155 -> 0 | L30: =L27*Assumption!$E$155 -> 0 | ... EF30: =EF27*Assumption!$E$155 -> 0
A31: 스파&수영장&피트니스 | B31: 백만원 | C31: =SUM(E31:EF31) -> 29997.99 | E31: =E27*Assumption!$E$156 -> 0 | F31: =F27*Assumption!$E$156 -> 0 | G31: =G27*Assumption!$E$156 -> 0 | H31: =H27*Assumption!$E$156 -> 0 | I31: =I27*Assumption!$E$156 -> 0 | J31: =J27*Assumption!$E$156 -> 0 | K31: =K27*Assumption!$E$156 -> 0 | L31: =L27*Assumption!$E$156 -> 0 | ... EF31: =EF27*Assumption!$E$156 -> 0
A32: 파인다이닝/ADD | B32: 백만원 | C32: =SUM(E32:EF32) -> 96422.111 | E32: =E27*Assumption!$E$157 -> 0 | F32: =F27*Assumption!$E$157 -> 0 | G32: =G27*Assumption!$E$157 -> 0 | H32: =H27*Assumption!$E$157 -> 0 | I32: =I27*Assumption!$E$157 -> 0 | J32: =J27*Assumption!$E$157 -> 0 | K32: =K27*Assumption!$E$157 -> 0 | L32: =L27*Assumption!$E$157 -> 0 | ... EF32: =EF27*Assumption!$E$157 -> 0
A33: 휴게시설 | B33: 백만원 | C33: =SUM(E33:EF33) -> 42854.272 | E33: =E27*Assumption!$E$158 -> 0 | F33: =F27*Assumption!$E$158 -> 0 | G33: =G27*Assumption!$E$158 -> 0 | H33: =H27*Assumption!$E$158 -> 0 | I33: =I27*Assumption!$E$158 -> 0 | J33: =J27*Assumption!$E$158 -> 0 | K33: =K27*Assumption!$E$158 -> 0 | L33: =L27*Assumption!$E$158 -> 0 | ... EF33: =EF27*Assumption!$E$158 -> 0
A34: BOH | B34: 백만원 | C34: =SUM(E34:EF34) -> 8570.8543 | E34: =E33*Assumption!$E$159 -> 0 | F34: =F33*Assumption!$E$159 -> 0 | G34: =G33*Assumption!$E$159 -> 0 | H34: =H33*Assumption!$E$159 -> 0 | I34: =I33*Assumption!$E$159 -> 0 | J34: =J33*Assumption!$E$159 -> 0 | K34: =K33*Assumption!$E$159 -> 0 | L34: =L33*Assumption!$E$159 -> 0 | ... EF34: =EF33*Assumption!$E$159 -> 0
A35: 오피스 임대료 | B35: 백만원 | C35: =SUM(E35:EF35) -> 84940.506 | E35: =(E14=1)*Assumption!$E$169*Assumption!$E$170/1000*(1+Assumption!$E$172)^INT((E15-1)/Assumption!$E$173)*(1-CHOOSE(MIN(MAX(E16,1),3),Assumption!$E$175,Assumption!$E$176,Assumption!$E$177)) -> 0 | F35: =(F14=1)*Assumption!$E$169*Assumption!$E$170/1000*(1+Assumption!$E$172)^INT((F15-1)/Assumption!$E$173)*(1-CHOOSE(MIN(MAX(F16,1),3),Assumption!$E$175,Assumption!$E$176,Assumption!$E$177)) -> 0 | G35: =(G14=1)*Assumption!$E$169*Assumption!$E$170/1000*(1+Assumption!$E$172)^INT((G15-1)/Assumption!$E$173)*(1-CHOOSE(MIN(MAX(G16,1),3),Assumption!$E$175,Assumption!$E$176,Assumption!$E$177)) -> 0 | H35: =(H14=1)*Assumption!$E$169*Assumption!$E$170/1000*(1+Assumption!$E$172)^INT((H15-1)/Assumption!$E$173)*(1-CHOOSE(MIN(MAX(H16,1),3),Assumption!$E$175,Assumption!$E$176,Assumption!$E$177)) -> 0 | I35: =(I14=1)*Assumption!$E$169*Assumption!$E$170/1000*(1+Assumption!$E$172)^INT((I15-1)/Assumption!$E$173)*(1-CHOOSE(MIN(MAX(I16,1),3),Assumption!$E$175,Assumption!$E$176,Assumption!$E$177)) -> 0 | J35: =(J14=1)*Assumption!$E$169*Assumption!$E$170/1000*(1+Assumption!$E$172)^INT((J15-1)/Assumption!$E$173)*(1-CHOOSE(MIN(MAX(J16,1),3),Assumption!$E$175,Assumption!$E$176,Assumption!$E$177)) -> 0 | K35: =(K14=1)*Assumption!$E$169*Assumption!$E$170/1000*(1+Assumption!$E$172)^INT((K15-1)/Assumption!$E$173)*(1-CHOOSE(MIN(MAX(K16,1),3),Assumption!$E$175,Assumption!$E$176,Assumption!$E$177)) -> 0 | L35: =(L14=1)*Assumption!$E$169*Assumption!$E$170/1000*(1+Assumption!$E$172)^INT((L15-1)/Assumption!$E$173)*(1-CHOOSE(MIN(MAX(L16,1),3),Assumption!$E$175,Assumption!$E$176,Assumption!$E$177)) -> 0 | ... EF35: =(EF14=1)*Assumption!$E$169*Assumption!$E$170/1000*(1+Assumption!$E$172)^INT((EF15-1)/Assumption!$E$173)*(1-CHOOSE(MIN(MAX(EF16,1),3),Assumption!$E$175,Assumption!$E$176,Assumption!$E$177)) -> 0
A36: 메디컬 임대료 | B36: 백만원 | C36: =SUM(E36:EF36) -> 8886.1692 | E36: =(E14=1)*Assumption!$E$187*Assumption!$E$188/1000*(1+Assumption!$E$190)^INT((E15-1)/Assumption!$E$191)*(1-CHOOSE(MIN(MAX(E16,1),3),Assumption!$E$193,Assumption!$E$194,Assumption!$E$195)) -> 0 | F36: =(F14=1)*Assumption!$E$187*Assumption!$E$188/1000*(1+Assumption!$E$190)^INT((F15-1)/Assumption!$E$191)*(1-CHOOSE(MIN(MAX(F16,1),3),Assumption!$E$193,Assumption!$E$194,Assumption!$E$195)) -> 0 | G36: =(G14=1)*Assumption!$E$187*Assumption!$E$188/1000*(1+Assumption!$E$190)^INT((G15-1)/Assumption!$E$191)*(1-CHOOSE(MIN(MAX(G16,1),3),Assumption!$E$193,Assumption!$E$194,Assumption!$E$195)) -> 0 | H36: =(H14=1)*Assumption!$E$187*Assumption!$E$188/1000*(1+Assumption!$E$190)^INT((H15-1)/Assumption!$E$191)*(1-CHOOSE(MIN(MAX(H16,1),3),Assumption!$E$193,Assumption!$E$194,Assumption!$E$195)) -> 0 | I36: =(I14=1)*Assumption!$E$187*Assumption!$E$188/1000*(1+Assumption!$E$190)^INT((I15-1)/Assumption!$E$191)*(1-CHOOSE(MIN(MAX(I16,1),3),Assumption!$E$193,Assumption!$E$194,Assumption!$E$195)) -> 0 | J36: =(J14=1)*Assumption!$E$187*Assumption!$E$188/1000*(1+Assumption!$E$190)^INT((J15-1)/Assumption!$E$191)*(1-CHOOSE(MIN(MAX(J16,1),3),Assumption!$E$193,Assumption!$E$194,Assumption!$E$195)) -> 0 | K36: =(K14=1)*Assumption!$E$187*Assumption!$E$188/1000*(1+Assumption!$E$190)^INT((K15-1)/Assumption!$E$191)*(1-CHOOSE(MIN(MAX(K16,1),3),Assumption!$E$193,Assumption!$E$194,Assumption!$E$195)) -> 0 | L36: =(L14=1)*Assumption!$E$187*Assumption!$E$188/1000*(1+Assumption!$E$190)^INT((L15-1)/Assumption!$E$191)*(1-CHOOSE(MIN(MAX(L16,1),3),Assumption!$E$193,Assumption!$E$194,Assumption!$E$195)) -> 0 | ... EF36: =(EF14=1)*Assumption!$E$187*Assumption!$E$188/1000*(1+Assumption!$E$190)^INT((EF15-1)/Assumption!$E$191)*(1-CHOOSE(MIN(MAX(EF16,1),3),Assumption!$E$193,Assumption!$E$194,Assumption!$E$195)) -> 0
A37: 스파2.0 임대료 | B37: 백만원 | C37: =SUM(E37:EF37) -> 9520.8956 | E37: =(E14=1)*Assumption!$E$200*Assumption!$E$201/1000*(1+Assumption!$E$203)^INT((E15-1)/Assumption!$E$204)*(1-CHOOSE(MIN(MAX(E16,1),3),Assumption!$E$206,Assumption!$E$207,Assumption!$E$208)) -> 0 | F37: =(F14=1)*Assumption!$E$200*Assumption!$E$201/1000*(1+Assumption!$E$203)^INT((F15-1)/Assumption!$E$204)*(1-CHOOSE(MIN(MAX(F16,1),3),Assumption!$E$206,Assumption!$E$207,Assumption!$E$208)) -> 0 | G37: =(G14=1)*Assumption!$E$200*Assumption!$E$201/1000*(1+Assumption!$E$203)^INT((G15-1)/Assumption!$E$204)*(1-CHOOSE(MIN(MAX(G16,1),3),Assumption!$E$206,Assumption!$E$207,Assumption!$E$208)) -> 0 | H37: =(H14=1)*Assumption!$E$200*Assumption!$E$201/1000*(1+Assumption!$E$203)^INT((H15-1)/Assumption!$E$204)*(1-CHOOSE(MIN(MAX(H16,1),3),Assumption!$E$206,Assumption!$E$207,Assumption!$E$208)) -> 0 | I37: =(I14=1)*Assumption!$E$200*Assumption!$E$201/1000*(1+Assumption!$E$203)^INT((I15-1)/Assumption!$E$204)*(1-CHOOSE(MIN(MAX(I16,1),3),Assumption!$E$206,Assumption!$E$207,Assumption!$E$208)) -> 0 | J37: =(J14=1)*Assumption!$E$200*Assumption!$E$201/1000*(1+Assumption!$E$203)^INT((J15-1)/Assumption!$E$204)*(1-CHOOSE(MIN(MAX(J16,1),3),Assumption!$E$206,Assumption!$E$207,Assumption!$E$208)) -> 0 | K37: =(K14=1)*Assumption!$E$200*Assumption!$E$201/1000*(1+Assumption!$E$203)^INT((K15-1)/Assumption!$E$204)*(1-CHOOSE(MIN(MAX(K16,1),3),Assumption!$E$206,Assumption!$E$207,Assumption!$E$208)) -> 0 | L37: =(L14=1)*Assumption!$E$200*Assumption!$E$201/1000*(1+Assumption!$E$203)^INT((L15-1)/Assumption!$E$204)*(1-CHOOSE(MIN(MAX(L16,1),3),Assumption!$E$206,Assumption!$E$207,Assumption!$E$208)) -> 0 | ... EF37: =(EF14=1)*Assumption!$E$200*Assumption!$E$201/1000*(1+Assumption!$E$203)^INT((EF15-1)/Assumption!$E$204)*(1-CHOOSE(MIN(MAX(EF16,1),3),Assumption!$E$206,Assumption!$E$207,Assumption!$E$208)) -> 0
A38: 판매시설 임대료 | B38: 백만원 | C38: =SUM(E38:EF38) -> 16700.724 | E38: =(E14=1)*Assumption!$E$213*Assumption!$E$214/1000*(1+Assumption!$E$216)^INT((E15-1)/Assumption!$E$217)*(1-CHOOSE(MIN(MAX(E16,1),3),Assumption!$E$219,Assumption!$E$220,Assumption!$E$221)) -> 0 | F38: =(F14=1)*Assumption!$E$213*Assumption!$E$214/1000*(1+Assumption!$E$216)^INT((F15-1)/Assumption!$E$217)*(1-CHOOSE(MIN(MAX(F16,1),3),Assumption!$E$219,Assumption!$E$220,Assumption!$E$221)) -> 0 | G38: =(G14=1)*Assumption!$E$213*Assumption!$E$214/1000*(1+Assumption!$E$216)^INT((G15-1)/Assumption!$E$217)*(1-CHOOSE(MIN(MAX(G16,1),3),Assumption!$E$219,Assumption!$E$220,Assumption!$E$221)) -> 0 | H38: =(H14=1)*Assumption!$E$213*Assumption!$E$214/1000*(1+Assumption!$E$216)^INT((H15-1)/Assumption!$E$217)*(1-CHOOSE(MIN(MAX(H16,1),3),Assumption!$E$219,Assumption!$E$220,Assumption!$E$221)) -> 0 | I38: =(I14=1)*Assumption!$E$213*Assumption!$E$214/1000*(1+Assumption!$E$216)^INT((I15-1)/Assumption!$E$217)*(1-CHOOSE(MIN(MAX(I16,1),3),Assumption!$E$219,Assumption!$E$220,Assumption!$E$221)) -> 0 | J38: =(J14=1)*Assumption!$E$213*Assumption!$E$214/1000*(1+Assumption!$E$216)^INT((J15-1)/Assumption!$E$217)*(1-CHOOSE(MIN(MAX(J16,1),3),Assumption!$E$219,Assumption!$E$220,Assumption!$E$221)) -> 0 | K38: =(K14=1)*Assumption!$E$213*Assumption!$E$214/1000*(1+Assumption!$E$216)^INT((K15-1)/Assumption!$E$217)*(1-CHOOSE(MIN(MAX(K16,1),3),Assumption!$E$219,Assumption!$E$220,Assumption!$E$221)) -> 0 | L38: =(L14=1)*Assumption!$E$213*Assumption!$E$214/1000*(1+Assumption!$E$216)^INT((L15-1)/Assumption!$E$217)*(1-CHOOSE(MIN(MAX(L16,1),3),Assumption!$E$219,Assumption!$E$220,Assumption!$E$221)) -> 0 | ... EF38: =(EF14=1)*Assumption!$E$213*Assumption!$E$214/1000*(1+Assumption!$E$216)^INT((EF15-1)/Assumption!$E$217)*(1-CHOOSE(MIN(MAX(EF16,1),3),Assumption!$E$219,Assumption!$E$220,Assumption!$E$221)) -> 0
A39: 국제학교 임대료 | B39: 백만원 | C39: =SUM(E39:EF39) -> 4436.2652 | E39: =(E14=1)*Assumption!$E$226*Assumption!$E$227/1000*(1+Assumption!$E$229)^INT((E15-1)/Assumption!$E$230)*(1-CHOOSE(MIN(MAX(E16,1),3),Assumption!$E$232,Assumption!$E$233,Assumption!$E$234)) -> 0 | F39: =(F14=1)*Assumption!$E$226*Assumption!$E$227/1000*(1+Assumption!$E$229)^INT((F15-1)/Assumption!$E$230)*(1-CHOOSE(MIN(MAX(F16,1),3),Assumption!$E$232,Assumption!$E$233,Assumption!$E$234)) -> 0 | G39: =(G14=1)*Assumption!$E$226*Assumption!$E$227/1000*(1+Assumption!$E$229)^INT((G15-1)/Assumption!$E$230)*(1-CHOOSE(MIN(MAX(G16,1),3),Assumption!$E$232,Assumption!$E$233,Assumption!$E$234)) -> 0 | H39: =(H14=1)*Assumption!$E$226*Assumption!$E$227/1000*(1+Assumption!$E$229)^INT((H15-1)/Assumption!$E$230)*(1-CHOOSE(MIN(MAX(H16,1),3),Assumption!$E$232,Assumption!$E$233,Assumption!$E$234)) -> 0 | I39: =(I14=1)*Assumption!$E$226*Assumption!$E$227/1000*(1+Assumption!$E$229)^INT((I15-1)/Assumption!$E$230)*(1-CHOOSE(MIN(MAX(I16,1),3),Assumption!$E$232,Assumption!$E$233,Assumption!$E$234)) -> 0 | J39: =(J14=1)*Assumption!$E$226*Assumption!$E$227/1000*(1+Assumption!$E$229)^INT((J15-1)/Assumption!$E$230)*(1-CHOOSE(MIN(MAX(J16,1),3),Assumption!$E$232,Assumption!$E$233,Assumption!$E$234)) -> 0 | K39: =(K14=1)*Assumption!$E$226*Assumption!$E$227/1000*(1+Assumption!$E$229)^INT((K15-1)/Assumption!$E$230)*(1-CHOOSE(MIN(MAX(K16,1),3),Assumption!$E$232,Assumption!$E$233,Assumption!$E$234)) -> 0 | L39: =(L14=1)*Assumption!$E$226*Assumption!$E$227/1000*(1+Assumption!$E$229)^INT((L15-1)/Assumption!$E$230)*(1-CHOOSE(MIN(MAX(L16,1),3),Assumption!$E$232,Assumption!$E$233,Assumption!$E$234)) -> 0 | ... EF39: =(EF14=1)*Assumption!$E$226*Assumption!$E$227/1000*(1+Assumption!$E$229)^INT((EF15-1)/Assumption!$E$230)*(1-CHOOSE(MIN(MAX(EF16,1),3),Assumption!$E$232,Assumption!$E$233,Assumption!$E$234)) -> 0
A40: 영어유치원 임대료 | B40: 백만원 | C40: =SUM(E40:EF40) -> 1602.7028 | E40: =(E14=1)*Assumption!$E$239*Assumption!$E$240/1000*(1+Assumption!$E$242)^INT((E15-1)/Assumption!$E$243)*(1-CHOOSE(MIN(MAX(E16,1),3),Assumption!$E$245,Assumption!$E$246,Assumption!$E$247)) -> 0 | F40: =(F14=1)*Assumption!$E$239*Assumption!$E$240/1000*(1+Assumption!$E$242)^INT((F15-1)/Assumption!$E$243)*(1-CHOOSE(MIN(MAX(F16,1),3),Assumption!$E$245,Assumption!$E$246,Assumption!$E$247)) -> 0 | G40: =(G14=1)*Assumption!$E$239*Assumption!$E$240/1000*(1+Assumption!$E$242)^INT((G15-1)/Assumption!$E$243)*(1-CHOOSE(MIN(MAX(G16,1),3),Assumption!$E$245,Assumption!$E$246,Assumption!$E$247)) -> 0 | H40: =(H14=1)*Assumption!$E$239*Assumption!$E$240/1000*(1+Assumption!$E$242)^INT((H15-1)/Assumption!$E$243)*(1-CHOOSE(MIN(MAX(H16,1),3),Assumption!$E$245,Assumption!$E$246,Assumption!$E$247)) -> 0 | I40: =(I14=1)*Assumption!$E$239*Assumption!$E$240/1000*(1+Assumption!$E$242)^INT((I15-1)/Assumption!$E$243)*(1-CHOOSE(MIN(MAX(I16,1),3),Assumption!$E$245,Assumption!$E$246,Assumption!$E$247)) -> 0 | J40: =(J14=1)*Assumption!$E$239*Assumption!$E$240/1000*(1+Assumption!$E$242)^INT((J15-1)/Assumption!$E$243)*(1-CHOOSE(MIN(MAX(J16,1),3),Assumption!$E$245,Assumption!$E$246,Assumption!$E$247)) -> 0 | K40: =(K14=1)*Assumption!$E$239*Assumption!$E$240/1000*(1+Assumption!$E$242)^INT((K15-1)/Assumption!$E$243)*(1-CHOOSE(MIN(MAX(K16,1),3),Assumption!$E$245,Assumption!$E$246,Assumption!$E$247)) -> 0 | L40: =(L14=1)*Assumption!$E$239*Assumption!$E$240/1000*(1+Assumption!$E$242)^INT((L15-1)/Assumption!$E$243)*(1-CHOOSE(MIN(MAX(L16,1),3),Assumption!$E$245,Assumption!$E$246,Assumption!$E$247)) -> 0 | ... EF40: =(EF14=1)*Assumption!$E$239*Assumption!$E$240/1000*(1+Assumption!$E$242)^INT((EF15-1)/Assumption!$E$243)*(1-CHOOSE(MIN(MAX(EF16,1),3),Assumption!$E$245,Assumption!$E$246,Assumption!$E$247)) -> 0
A41: 운영수입 합계 | B41: 백만원 | C41: =SUM(E41:EF41) -> 1022866.3 | E41: =SUM(E21:E40) -> 0 | F41: =SUM(F21:F40) -> 0 | G41: =SUM(G21:G40) -> 0 | H41: =SUM(H21:H40) -> 0 | I41: =SUM(I21:I40) -> 0 | J41: =SUM(J21:J40) -> 0 | K41: =SUM(K21:K40) -> 0 | L41: =SUM(L21:L40) -> 0 | ... EF41: =SUM(EF21:EF40) -> 0
A43: 직접운영비용
A44: 시니어 운영비(일반+소모품) | B44: 백만원 | C44: =SUM(E44:EF44) -> 88377.554 | E44: =(E21+E22)*(Assumption!$E$96+Assumption!$E$97) -> 0 | F44: =(F21+F22)*(Assumption!$E$96+Assumption!$E$97) -> 0 | G44: =(G21+G22)*(Assumption!$E$96+Assumption!$E$97) -> 0 | H44: =(H21+H22)*(Assumption!$E$96+Assumption!$E$97) -> 0 | I44: =(I21+I22)*(Assumption!$E$96+Assumption!$E$97) -> 0 | J44: =(J21+J22)*(Assumption!$E$96+Assumption!$E$97) -> 0 | K44: =(K21+K22)*(Assumption!$E$96+Assumption!$E$97) -> 0 | L44: =(L21+L22)*(Assumption!$E$96+Assumption!$E$97) -> 0 | ... EF44: =(EF21+EF22)*(Assumption!$E$96+Assumption!$E$97) -> 0
...

Sheet Annual
A1: 연도별 요약 (CF 시트 집계) — 단위: 백만원
A3: 구분 | B3: 합계 | C3: =YEAR(Assumption!$E$8) -> 2026 | D3: =C3+1 -> 2027 | E3: =D3+1 -> 2028 | F3: =E3+1 -> 2029 | G3: =F3+1 -> 2030 | H3: =G3+1 -> 2031 | I3: =H3+1 -> 2032 | J3: =I3+1 -> 2033 | K3: =J3+1 -> 2034 | ... M3: =L3+1 -> 2036
A4: 운영
A5: 운영수입 합계 | B5: =SUM(C5:M5) -> 1022866.3 | C5: =SUMIF(CF!$E$7:$EF$7,C$3,CF!$E$41:$EF$41) -> 0 | D5: =SUMIF(CF!$E$7:$EF$7,D$3,CF!$E$41:$EF$41) -> 0 | E5: =SUMIF(CF!$E$7:$EF$7,E$3,CF!$E$41:$EF$41) -> 0 | F5: =SUMIF(CF!$E$7:$EF$7,F$3,CF!$E$41:$EF$41) -> 0 | G5: =SUMIF(CF!$E$7:$EF$7,G$3,CF!$E$41:$EF$41) -> 0 | H5: =SUMIF(CF!$E$7:$EF$7,H$3,CF!$E$41:$EF$41) -> 145507.98 | I5: =SUMIF(CF!$E$7:$EF$7,I$3,CF!$E$41:$EF$41) -> 200951.57 | J5: =SUMIF(CF!$E$7:$EF$7,J$3,CF!$E$41:$EF$41) -> 209248.63 | ... M5: =SUMIF(CF!$E$7:$EF$7,M$3,CF!$E$41:$EF$41) -> 36022.258
A6: 직접운영비용 | B6: =SUM(C6:M6) -> 706913.04 | C6: =SUMIF(CF!$E$7:$EF$7,C$3,CF!$E$56:$EF$56) -> 0 | D6: =SUMIF(CF!$E$7:$EF$7,D$3,CF!$E$56:$EF$56) -> 0 | E6: =SUMIF(CF!$E$7:$EF$7,E$3,CF!$E$56:$EF$56) -> 0 | F6: =SUMIF(CF!$E$7:$EF$7,F$3,CF!$E$56:$EF$56) -> 0 | G6: =SUMIF(CF!$E$7:$EF$7,G$3,CF!$E$56:$EF$56) -> 0 | H6: =SUMIF(CF!$E$7:$EF$7,H$3,CF!$E$56:$EF$56) -> 102004.83 | I6: =SUMIF(CF!$E$7:$EF$7,I$3,CF!$E$56:$EF$56) -> 138846.41 | J6: =SUMIF(CF!$E$7:$EF$7,J$3,CF!$E$56:$EF$56) -> 144187.65 | ... M6: =SUMIF(CF!$E$7:$EF$7,M$3,CF!$E$56:$EF$56) -> 24789.909
A7: NOI - 시니어 레지던스 | B7: =SUM(C7:M7) -> 32621.512 | C7: =SUMIF(CF!$E$7:$EF$7,C$3,CF!$E$59:$EF$59) -> 0 | D7: =SUMIF(CF!$E$7:$EF$7,D$3,CF!$E$59:$EF$59) -> 0 | E7: =SUMIF(CF!$E$7:$EF$7,E$3,CF!$E$59:$EF$59) -> 0 | F7: =SUMIF(CF!$E$7:$EF$7,F$3,CF!$E$59:$EF$59) -> 0 | G7: =SUMIF(CF!$E$7:$EF$7,G$3,CF!$E$59:$EF$59) -> 0 | H7: =SUMIF(CF!$E$7:$EF$7,H$3,CF!$E$59:$EF$59) -> 4591.644 | I7: =SUMIF(CF!$E$7:$EF$7,I$3,CF!$E$59:$EF$59) -> 6399.9149 | J7: =SUMIF(CF!$E$7:$EF$7,J$3,CF!$E$59:$EF$59) -> 6687.535 | ... M7: =SUMIF(CF!$E$7:$EF$7,M$3,CF!$E$59:$EF$59) -> 1163.4206
A8: NOI - 레지던스 | B8: =SUM(C8:M8) -> 42839.167 | C8: =SUMIF(CF!$E$7:$EF$7,C$3,CF!$E$60:$EF$60) -> 0 | D8: =SUMIF(CF!$E$7:$EF$7,D$3,CF!$E$60:$EF$60) -> 0 | E8: =SUMIF(CF!$E$7:$EF$7,E$3,CF!$E$60:$EF$60) -> 0 | F8: =SUMIF(CF!$E$7:$EF$7,F$3,CF!$E$60:$EF$60) -> 0 | G8: =SUMIF(CF!$E$7:$EF$7,G$3,CF!$E$60:$EF$60) -> 0 | H8: =SUMIF(CF!$E$7:$EF$7,H$3,CF!$E$60:$EF$60) -> 6131.9139 | I8: =SUMIF(CF!$E$7:$EF$7,I$3,CF!$E$60:$EF$60) -> 8419.127 | J8: =SUMIF(CF!$E$7:$EF$7,J$3,CF!$E$60:$EF$60) -> 8752.5996 | ... M8: =SUMIF(CF!$E$7:$EF$7,M$3,CF!$E$60:$EF$60) -> 1501.6699
A9: NOI - 호텔 | B9: =SUM(C9:M9) -> 132976.8 | C9: =SUMIF(CF!$E$7:$EF$7,C$3,CF!$E$61:$EF$61) -> 0 | D9: =SUMIF(CF!$E$7:$EF$7,D$3,CF!$E$61:$EF$61) -> 0 | E9: =SUMIF(CF!$E$7:$EF$7,E$3,CF!$E$61:$EF$61) -> 0 | F9: =SUMIF(CF!$E$7:$EF$7,F$3,CF!$E$61:$EF$61) -> 0 | G9: =SUMIF(CF!$E$7:$EF$7,G$3,CF!$E$61:$EF$61) -> 0 | H9: =SUMIF(CF!$E$7:$EF$7,H$3,CF!$E$61:$EF$61) -> 19034.038 | I9: =SUMIF(CF!$E$7:$EF$7,I$3,CF!$E$61:$EF$61) -> 26133.763 | J9: =SUMIF(CF!$E$7:$EF$7,J$3,CF!$E$61:$EF$61) -> 27168.893 | ... M9: =SUMIF(CF!$E$7:$EF$7,M$3,CF!$E$61:$EF$61) -> 4661.3246
A10: NOI - 오피스 | B10: =SUM(C10:M10) -> 66369.038 | C10: =SUMIF(CF!$E$7:$EF$7,C$3,CF!$E$62:$EF$62) -> 0 | D10: =SUMIF(CF!$E$7:$EF$7,D$3,CF!$E$62:$EF$62) -> 0 | E10: =SUMIF(CF!$E$7:$EF$7,E$3,CF!$E$62:$EF$62) -> 0 | F10: =SUMIF(CF!$E$7:$EF$7,F$3,CF!$E$62:$EF$62) -> 0 | G10: =SUMIF(CF!$E$7:$EF$7,G$3,CF!$E$62:$EF$62) -> 0 | H10: =SUMIF(CF!$E$7:$EF$7,H$3,CF!$E$62:$EF$62) -> 7156.6406 | I10: =SUMIF(CF!$E$7:$EF$7,I$3,CF!$E$62:$EF$62) -> 13113.878 | J10: =SUMIF(CF!$E$7:$EF$7,J$3,CF!$E$62:$EF$62) -> 14252.711 | ... M10: =SUMIF(CF!$E$7:$EF$7,M$3,CF!$E$62:$EF$62) -> 2479.5231
A11: NOI - 부대시설 | B11: =SUM(C11:M11) -> 41146.757 | C11: =SUMIF(CF!$E$7:$EF$7,C$3,CF!$E$63:$EF$63) -> 0 | D11: =SUMIF(CF!$E$7:$EF$7,D$3,CF!$E$63:$EF$63) -> 0 | E11: =SUMIF(CF!$E$7:$EF$7,E$3,CF!$E$63:$EF$63) -> 0 | F11: =SUMIF(CF!$E$7:$EF$7,F$3,CF!$E$63:$EF$63) -> 0 | G11: =SUMIF(CF!$E$7:$EF$7,G$3,CF!$E$63:$EF$63) -> 0 | H11: =SUMIF(CF!$E$7:$EF$7,H$3,CF!$E$63:$EF$63) -> 6588.9123 | I11: =SUMIF(CF!$E$7:$EF$7,I$3,CF!$E$63:$EF$63) -> 8038.473 | J11: =SUMIF(CF!$E$7:$EF$7,J$3,CF!$E$63:$EF$63) -> 8199.2425 | ... M11: =SUMIF(CF!$E$7:$EF$7,M$3,CF!$E$63:$EF$63) -> 1426.4101
A12: NOI 합계 | B12: =SUM(C12:M12) -> 315953.28 | C12: =SUMIF(CF!$E$7:$EF$7,C$3,CF!$E$64:$EF$64) -> 0 | D12: =SUMIF(CF!$E$7:$EF$7,D$3,CF!$E$64:$EF$64) -> 0 | E12: =SUMIF(CF!$E$7:$EF$7,E$3,CF!$E$64:$EF$64) -> 0 | F12: =SUMIF(CF!$E$7:$EF$7,F$3,CF!$E$64:$EF$64) -> 0 | G12: =SUMIF(CF!$E$7:$EF$7,G$3,CF!$E$64:$EF$64) -> 0 | H12: =SUMIF(CF!$E$7:$EF$7,H$3,CF!$E$64:$EF$64) -> 43503.149 | I12: =SUMIF(CF!$E$7:$EF$7,I$3,CF!$E$64:$EF$64) -> 62105.156 | J12: =SUMIF(CF!$E$7:$EF$7,J$3,CF!$E$64:$EF$64) -> 65060.981 | ... M12: =SUMIF(CF!$E$7:$EF$7,M$3,CF!$E$64:$EF$64) -> 11232.348
A13: 공통비용·리츠운용비 | B13: =SUM(C13:M13) -> 63114.79 | C13: =SUMIF(CF!$E$7:$EF$7,C$3,CF!$E$74:$EF$74) -> 0 | D13: =SUMIF(CF!$E$7:$EF$7,D$3,CF!$E$74:$EF$74) -> 0 | E13: =SUMIF(CF!$E$7:$EF$7,E$3,CF!$E$74:$EF$74) -> 0 | F13: =SUMIF(CF!$E$7:$EF$7,F$3,CF!$E$74:$EF$74) -> 0 | G13: =SUMIF(CF!$E$7:$EF$7,G$3,CF!$E$74:$EF$74) -> 0 | H13: =SUMIF(CF!$E$7:$EF$7,H$3,CF!$E$74:$EF$74) -> 8190.5983 | I13: =SUMIF(CF!$E$7:$EF$7,I$3,CF!$E$74:$EF$74) -> 10504.036 | J13: =SUMIF(CF!$E$7:$EF$7,J$3,CF!$E$74:$EF$74) -> 10820.972 | ... M13: =SUMIF(CF!$E$7:$EF$7,M$3,CF!$E$74:$EF$74) -> 11558.781
A14: 운영현금흐름 | B14: =SUM(C14:M14) -> 252838.49 | C14: =SUMIF(CF!$E$7:$EF$7,C$3,CF!$E$75:$EF$75) -> 0 | D14: =SUMIF(CF!$E$7:$EF$7,D$3,CF!$E$75:$EF$75) -> 0 | E14: =SUMIF(CF!$E$7:$EF$7,E$3,CF!$E$75:$EF$75) -> 0 | F14: =SUMIF(CF!$E$7:$EF$7,F$3,CF!$E$75:$EF$75) -> 0 | G14: =SUMIF(CF!$E$7:$EF$7,G$3,CF!$E$75:$EF$75) -> 0 | H14: =SUMIF(CF!$E$7:$EF$7,H$3,CF!$E$75:$EF$75) -> 35312.55 | I14: =SUMIF(CF!$E$7:$EF$7,I$3,CF!$E$75:$EF$75) -> 51601.119 | J14: =SUMIF(CF!$E$7:$EF$7,J$3,CF!$E$75:$EF$75) -> 54240.009 | ... M14: =SUMIF(CF!$E$7:$EF$7,M$3,CF!$E$75:$EF$75) -> -326.43265
A15: 개발 및 금융
A16: 개발사업비 집행 | B16: =SUM(C16:M16) -> 1401070.2 | C16: =SUMIF(CF!$E$7:$EF$7,C$3,CF!$E$100:$EF$100) -> 13874.924 | D16: =SUMIF(CF!$E$7:$EF$7,D$3,CF!$E$100:$EF$100) -> 253559.35 | E16: =SUMIF(CF!$E$7:$EF$7,E$3,CF!$E$100:$EF$100) -> 315713.7 | F16: =SUMIF(CF!$E$7:$EF$7,F$3,CF!$E$100:$EF$100) -> 457532.55 | G16: =SUMIF(CF!$E$7:$EF$7,G$3,CF!$E$100:$EF$100) -> 263441.5 | H16: =SUMIF(CF!$E$7:$EF$7,H$3,CF!$E$100:$EF$100) -> 96948.181 | I16: =SUMIF(CF!$E$7:$EF$7,I$3,CF!$E$100:$EF$100) -> 0 | J16: =SUMIF(CF!$E$7:$EF$7,J$3,CF!$E$100:$EF$100) -> 0 | ... M16: =SUMIF(CF!$E$7:$EF$7,M$3,CF!$E$100:$EF$100) -> 0
A17: PF 금융비용 | B17: =SUM(C17:M17) -> 95505.682 | C17: =SUMIF(CF!$E$7:$EF$7,C$3,CF!$E$112:$EF$112) -> 0 | D17: =SUMIF(CF!$E$7:$EF$7,D$3,CF!$E$112:$EF$112) -> 13410.991 | E17: =SUMIF(CF!$E$7:$EF$7,E$3,CF!$E$112:$EF$112) -> 6486.9755 | F17: =SUMIF(CF!$E$7:$EF$7,F$3,CF!$E$112:$EF$112) -> 24417.029 | G17: =SUMIF(CF!$E$7:$EF$7,G$3,CF!$E$112:$EF$112) -> 43104.746 | H17: =SUMIF(CF!$E$7:$EF$7,H$3,CF!$E$112:$EF$112) -> 8085.9409 | I17: =SUMIF(CF!$E$7:$EF$7,I$3,CF!$E$112:$EF$112) -> 0 | J17: =SUMIF(CF!$E$7:$EF$7,J$3,CF!$E$112:$EF$112) -> 0 | ... M17: =SUMIF(CF!$E$7:$EF$7,M$3,CF!$E$112:$EF$112) -> 0
A18: 담보대출 이자 | B18: =SUM(C18:M18) -> 198878.57 | C18: =SUMIF(CF!$E$7:$EF$7,C$3,CF!$E$129:$EF$129) -> 0 | D18: =SUMIF(CF!$E$7:$EF$7,D$3,CF!$E$129:$EF$129) -> 0 | E18: =SUMIF(CF!$E$7:$EF$7,E$3,CF!$E$129:$EF$129) -> 0 | F18: =SUMIF(CF!$E$7:$EF$7,F$3,CF!$E$129:$EF$129) -> 0 | G18: =SUMIF(CF!$E$7:$EF$7,G$3,CF!$E$129:$EF$129) -> 0 | H18: =SUMIF(CF!$E$7:$EF$7,H$3,CF!$E$129:$EF$129) -> 33146.428 | I18: =SUMIF(CF!$E$7:$EF$7,I$3,CF!$E$129:$EF$129) -> 39775.714 | J18: =SUMIF(CF!$E$7:$EF$7,J$3,CF!$E$129:$EF$129) -> 39775.714 | ... M18: =SUMIF(CF!$E$7:$EF$7,M$3,CF!$E$129:$EF$129) -> 6629.2857
A19: 담보대출 취급수수료 | B19: =SUM(C19:M19) -> 7596.6828 | C19: =SUMIF(CF!$E$7:$EF$7,C$3,CF!$E$128:$EF$128) -> 0 | D19: =SUMIF(CF!$E$7:$EF$7,D$3,CF!$E$128:$EF$128) -> 0 | E19: =SUMIF(CF!$E$7:$EF$7,E$3,CF!$E$128:$EF$128) -> 0 | F19: =SUMIF(CF!$E$7:$EF$7,F$3,CF!$E$128:$EF$128) -> 0 | G19: =SUMIF(CF!$E$7:$EF$7,G$3,CF!$E$128:$EF$128) -> 0 | H19: =SUMIF(CF!$E$7:$EF$7,H$3,CF!$E$128:$EF$128) -> 7596.6828 | I19: =SUMIF(CF!$E$7:$EF$7,I$3,CF!$E$128:$EF$128) -> 0 | J19: =SUMIF(CF!$E$7:$EF$7,J$3,CF!$E$128:$EF$128) -> 0 | ... M19: =SUMIF(CF!$E$7:$EF$7,M$3,CF!$E$128:$EF$128) -> 0
A20: 자금 유출입
A21: Equity 납입 | B21: =SUM(C21:M21) -> 287378.39 | C21: =SUMIF(CF!$E$7:$EF$7,C$3,CF!$E$142:$EF$142) -> 15820.18 | D21: =SUMIF(CF!$E$7:$EF$7,D$3,CF!$E$142:$EF$142) -> 271558.21 | E21: =SUMIF(CF!$E$7:$EF$7,E$3,CF!$E$142:$EF$142) -> 0 | F21: =SUMIF(CF!$E$7:$EF$7,F$3,CF!$E$142:$EF$142) -> 0 | G21: =SUMIF(CF!$E$7:$EF$7,G$3,CF!$E$142:$EF$142) -> 0 | H21: =SUMIF(CF!$E$7:$EF$7,H$3,CF!$E$142:$EF$142) -> 0 | I21: =SUMIF(CF!$E$7:$EF$7,I$3,CF!$E$142:$EF$142) -> 0 | J21: =SUMIF(CF!$E$7:$EF$7,J$3,CF!$E$142:$EF$142) -> 0 | ... M21: =SUMIF(CF!$E$7:$EF$7,M$3,CF!$E$142:$EF$142) -> 0
A22: 보증금 유입 | B22: =SUM(C22:M22) -> 941952 | C22: =SUMIF(CF!$E$7:$EF$7,C$3,CF!$E$84:$EF$84) -> 0 | D22: =SUMIF(CF!$E$7:$EF$7,D$3,CF!$E$84:$EF$84) -> 68060.16 | E22: =SUMIF(CF!$E$7:$EF$7,E$3,CF!$E$84:$EF$84) -> 136120.32 | F22: =SUMIF(CF!$E$7:$EF$7,F$3,CF!$E$84:$EF$84) -> 136120.32 | G22: =SUMIF(CF!$E$7:$EF$7,G$3,CF!$E$84:$EF$84) -> 136120.32 | H22: =SUMIF(CF!$E$7:$EF$7,H$3,CF!$E$84:$EF$84) -> 268980.48 | I22: =SUMIF(CF!$E$7:$EF$7,I$3,CF!$E$84:$EF$84) -> 183350.4 | J22: =SUMIF(CF!$E$7:$EF$7,J$3,CF!$E$84:$EF$84) -> 13200 | ... M22: =SUMIF(CF!$E$7:$EF$7,M$3,CF!$E$84:$EF$84) -> 0
A23: 보증금 승계(처분) | B23: =SUM(C23:M23) -> 941952 | C23: =SUMIF(CF!$E$7:$EF$7,C$3,CF!$E$85:$EF$85) -> 0 | D23: =SUMIF(CF!$E$7:$EF$7,D$3,CF!$E$85:$EF$85) -> 0 | E23: =SUMIF(CF!$E$7:$EF$7,E$3,CF!$E$85:$EF$85) -> 0 | F23: =SUMIF(CF!$E$7:$EF$7,F$3,CF!$E$85:$EF$85) -> 0 | G23: =SUMIF(CF!$E$7:$EF$7,G$3,CF!$E$85:$EF$85) -> 0 | H23: =SUMIF(CF!$E$7:$EF$7,H$3,CF!$E$85:$EF$85) -> 0 | I23: =SUMIF(CF!$E$7:$EF$7,I$3,CF!$E$85:$EF$85) -> 0 | J23: =SUMIF(CF!$E$7:$EF$7,J$3,CF!$E$85:$EF$85) -> 0 | ... M23: =SUMIF(CF!$E$7:$EF$7,M$3,CF!$E$85:$EF$85) -> 941952
A24: PF 인출 | B24: =SUM(C24:M24) -> 632619.29 | C24: =SUMIF(CF!$E$7:$EF$7,C$3,CF!$E$116:$EF$116) -> 0 | D24: =SUMIF(CF!$E$7:$EF$7,D$3,CF!$E$116:$EF$116) -> 0 | E24: =SUMIF(CF!$E$7:$EF$7,E$3,CF!$E$116:$EF$116) -> 108087.92 | F24: =SUMIF(CF!$E$7:$EF$7,F$3,CF!$E$116:$EF$116) -> 345404.15 | G24: =SUMIF(CF!$E$7:$EF$7,G$3,CF!$E$116:$EF$116) -> 169838.35 | H24: =SUMIF(CF!$E$7:$EF$7,H$3,CF!$E$116:$EF$116) -> 9288.8612 | I24: =SUMIF(CF!$E$7:$EF$7,I$3,CF!$E$116:$EF$116) -> 0 | J24: =SUMIF(CF!$E$7:$EF$7,J$3,CF!$E$116:$EF$116) -> 0 | ... M24: =SUMIF(CF!$E$7:$EF$7,M$3,CF!$E$116:$EF$116) -> 0
A25: PF 상환 | B25: =SUM(C25:M25) -> 632619.29 | C25: =SUMIF(CF!$E$7:$EF$7,C$3,CF!$E$120:$EF$120) -> 0 | D25: =SUMIF(CF!$E$7:$EF$7,D$3,CF!$E$120:$EF$120) -> 0 | E25: =SUMIF(CF!$E$7:$EF$7,E$3,CF!$E$120:$EF$120) -> 0 | F25: =SUMIF(CF!$E$7:$EF$7,F$3,CF!$E$120:$EF$120) -> 0 | G25: =SUMIF(CF!$E$7:$EF$7,G$3,CF!$E$120:$EF$120) -> 0 | H25: =SUMIF(CF!$E$7:$EF$7,H$3,CF!$E$120:$EF$120) -> 632619.29 | I25: =SUMIF(CF!$E$7:$EF$7,I$3,CF!$E$120:$EF$120) -> 0 | J25: =SUMIF(CF!$E$7:$EF$7,J$3,CF!$E$120:$EF$120) -> 0 | ... M25: =SUMIF(CF!$E$7:$EF$7,M$3,CF!$E$120:$EF$120) -> 0
A26: 담보대출 인출 | B26: =SUM(C26:M26) -> 759668.28 | C26: =SUMIF(CF!$E$7:$EF$7,C$3,CF!$E$127:$EF$127) -> 0 | D26: =SUMIF(CF!$E$7:$EF$7,D$3,CF!$E$127:$EF$127) -> 0 | E26: =SUMIF(CF!$E$7:$EF$7,E$3,CF!$E$127:$EF$127) -> 0 | F26: =SUMIF(CF!$E$7:$EF$7,F$3,CF!$E$127:$EF$127) -> 0 | G26: =SUMIF(CF!$E$7:$EF$7,G$3,CF!$E$127:$EF$127) -> 0 | H26: =SUMIF(CF!$E$7:$EF$7,H$3,CF!$E$127:$EF$127) -> 759668.28 | I26: =SUMIF(CF!$E$7:$EF$7,I$3,CF!$E$127:$EF$127) -> 0 | J26: =SUMIF(CF!$E$7:$EF$7,J$3,CF!$E$127:$EF$127) -> 0 | ... M26: =SUMIF(CF!$E$7:$EF$7,M$3,CF!$E$127:$EF$127) -> 0
A27: 담보대출 상환 | B27: =SUM(C27:M27) -> 759668.28 | C27: =SUMIF(CF!$E$7:$EF$7,C$3,CF!$E$130:$EF$130) -> 0 | D27: =SUMIF(CF!$E$7:$EF$7,D$3,CF!$E$130:$EF$130) -> 0 | E27: =SUMIF(CF!$E$7:$EF$7,E$3,CF!$E$130:$EF$130) -> 0 | F27: =SUMIF(CF!$E$7:$EF$7,F$3,CF!$E$130:$EF$130) -> 0 | G27: =SUMIF(CF!$E$7:$EF$7,G$3,CF!$E$130:$EF$130) -> 0 | H27: =SUMIF(CF!$E$7:$EF$7,H$3,CF!$E$130:$EF$130) -> 0 | I27: =SUMIF(CF!$E$7:$EF$7,I$3,CF!$E$130:$EF$130) -> 0 | J27: =SUMIF(CF!$E$7:$EF$7,J$3,CF!$E$130:$EF$130) -> 0 | ... M27: =SUMIF(CF!$E$7:$EF$7,M$3,CF!$E$130:$EF$130) -> 759668.28
A28: 매각대금 | B28: =SUM(C28:M28) -> 1824235.9 | C28: =SUMIF(CF!$E$7:$EF$7,C$3,CF!$E$145:$EF$145) -> 0 | D28: =SUMIF(CF!$E$7:$EF$7,D$3,CF!$E$145:$EF$145) -> 0 | E28: =SUMIF(CF!$E$7:$EF$7,E$3,CF!$E$145:$EF$145) -> 0 | F28: =SUMIF(CF!$E$7:$EF$7,F$3,CF!$E$145:$EF$145) -> 0 | G28: =SUMIF(CF!$E$7:$EF$7,G$3,CF!$E$145:$EF$145) -> 0 | H28: =SUMIF(CF!$E$7:$EF$7,H$3,CF!$E$145:$EF$145) -> 0 | I28: =SUMIF(CF!$E$7:$EF$7,I$3,CF!$E$145:$EF$145) -> 0 | J28: =SUMIF(CF!$E$7:$EF$7,J$3,CF!$E$145:$EF$145) -> 0 | ... M28: =SUMIF(CF!$E$7:$EF$7,M$3,CF!$E$145:$EF$145) -> 1824235.9
A29: 분배
A30: 우선주 배당 | B30: =SUM(C30:M30) -> 91331.559 | C30: =SUMIF(CF!$E$7:$EF$7,C$3,CF!$E$165:$EF$165) -> 0 | D30: =SUMIF(CF!$E$7:$EF$7,D$3,CF!$E$165:$EF$165) -> 0 | E30: =SUMIF(CF!$E$7:$EF$7,E$3,CF!$E$165:$EF$165) -> 0 | F30: =SUMIF(CF!$E$7:$EF$7,F$3,CF!$E$165:$EF$165) -> 0 | G30: =SUMIF(CF!$E$7:$EF$7,G$3,CF!$E$165:$EF$165) -> 0 | H30: =SUMIF(CF!$E$7:$EF$7,H$3,CF!$E$165:$EF$165) -> 13776.401 | I30: =SUMIF(CF!$E$7:$EF$7,I$3,CF!$E$165:$EF$165) -> 24599.06 | J30: =SUMIF(CF!$E$7:$EF$7,J$3,CF!$E$165:$EF$165) -> 28910.077 | ... M30: =SUMIF(CF!$E$7:$EF$7,M$3,CF!$E$165:$EF$165) -> 4117.9416
A31: 우선주 원금상환 | B31: =SUM(C31:M31) -> 201164.87 | C31: =SUMIF(CF!$E$7:$EF$7,C$3,CF!$E$166:$EF$166) -> 0 | D31: =SUMIF(CF!$E$7:$EF$7,D$3,CF!$E$166:$EF$166) -> 0 | E31: =SUMIF(CF!$E$7:$EF$7,E$3,CF!$E$166:$EF$166) -> 0 | F31: =SUMIF(CF!$E$7:$EF$7,F$3,CF!$E$166:$EF$166) -> 0 | G31: =SUMIF(CF!$E$7:$EF$7,G$3,CF!$E$166:$EF$166) -> 0 | H31: =SUMIF(CF!$E$7:$EF$7,H$3,CF!$E$166:$EF$166) -> 0 | I31: =SUMIF(CF!$E$7:$EF$7,I$3,CF!$E$166:$EF$166) -> 0 | J31: =SUMIF(CF!$E$7:$EF$7,J$3,CF!$E$166:$EF$166) -> 0 | ... M31: =SUMIF(CF!$E$7:$EF$7,M$3,CF!$E$166:$EF$166) -> 201164.87
A32: 보통주 분배 | B32: =SUM(C32:M32) -> 443763.15 | C32: =SUMIF(CF!$E$7:$EF$7,C$3,CF!$E$168:$EF$168) -> 0 | D32: =SUMIF(CF!$E$7:$EF$7,D$3,CF!$E$168:$EF$168) -> 0 | E32: =SUMIF(CF!$E$7:$EF$7,E$3,CF!$E$168:$EF$168) -> 0 | F32: =SUMIF(CF!$E$7:$EF$7,F$3,CF!$E$168:$EF$168) -> 0 | G32: =SUMIF(CF!$E$7:$EF$7,G$3,CF!$E$168:$EF$168) -> 0 | H32: =SUMIF(CF!$E$7:$EF$7,H$3,CF!$E$168:$EF$168) -> 0 | I32: =SUMIF(CF!$E$7:$EF$7,I$3,CF!$E$168:$EF$168) -> 0 | J32: =SUMIF(CF!$E$7:$EF$7,J$3,CF!$E$168:$EF$168) -> 0 | ... M32: =SUMIF(CF!$E$7:$EF$7,M$3,CF!$E$168:$EF$168) -> 402141.85
A33: 보통주 CF | B33: =SUM(C33:M33) -> 357549.63 | C33: =SUMIF(CF!$E$7:$EF$7,C$3,CF!$E$171:$EF$171) -> -15820.18 | D33: =SUMIF(CF!$E$7:$EF$7,D$3,CF!$E$171:$EF$171) -> -70393.336 | E33: =SUMIF(CF!$E$7:$EF$7,E$3,CF!$E$171:$EF$171) -> 0 | F33: =SUMIF(CF!$E$7:$EF$7,F$3,CF!$E$171:$EF$171) -> 0 | G33: =SUMIF(CF!$E$7:$EF$7,G$3,CF!$E$171:$EF$171) -> 0 | H33: =SUMIF(CF!$E$7:$EF$7,H$3,CF!$E$171:$EF$171) -> 0 | I33: =SUMIF(CF!$E$7:$EF$7,I$3,CF!$E$171:$EF$171) -> 0 | J33: =SUMIF(CF!$E$7:$EF$7,J$3,CF!$E$171:$EF$171) -> 0 | ... M33: =SUMIF(CF!$E$7:$EF$7,M$3,CF!$E$171:$EF$171) -> 402141.85
A34: 우선주 CF | B34: =SUM(C34:M34) -> 91331.559 | C34: =SUMIF(CF!$E$7:$EF$7,C$3,CF!$E$172:$EF$172) -> 0 | D34: =SUMIF(CF!$E$7:$EF$7,D$3,CF!$E$172:$EF$172) -> -201164.87 | E34: =SUMIF(CF!$E$7:$EF$7,E$3,CF!$E$172:$EF$172) -> 0 | F34: =SUMIF(CF!$E$7:$EF$7,F$3,CF!$E$172:$EF$172) -> 0 | G34: =SUMIF(CF!$E$7:$EF$7,G$3,CF!$E$172:$EF$172) -> 0 | H34: =SUMIF(CF!$E$7:$EF$7,H$3,CF!$E$172:$EF$172) -> 13776.401 | I34: =SUMIF(CF!$E$7:$EF$7,I$3,CF!$E$172:$EF$172) -> 24599.06 | J34: =SUMIF(CF!$E$7:$EF$7,J$3,CF!$E$172:$EF$172) -> 28910.077 | ... M34: =SUMIF(CF!$E$7:$EF$7,M$3,CF!$E$172:$EF$172) -> 205282.81
A35: 전체 Equity CF | B35: =SUM(C35:M35) -> 448881.19 | C35: =SUMIF(CF!$E$7:$EF$7,C$3,CF!$E$173:$EF$173) -> -15820.18 | D35: =SUMIF(CF!$E$7:$EF$7,D$3,CF!$E$173:$EF$173) -> -271558.21 | E35: =SUMIF(CF!$E$7:$EF$7,E$3,CF!$E$173:$EF$173) -> 0 | F35: =SUMIF(CF!$E$7:$EF$7,F$3,CF!$E$173:$EF$173) -> 0 | G35: =SUMIF(CF!$E$7:$EF$7,G$3,CF!$E$173:$EF$173) -> 0 | H35: =SUMIF(CF!$E$7:$EF$7,H$3,CF!$E$173:$EF$173) -> 13776.401 | I35: =SUMIF(CF!$E$7:$EF$7,I$3,CF!$E$173:$EF$173) -> 24599.06 | J35: =SUMIF(CF!$E$7:$EF$7,J$3,CF!$E$173:$EF$173) -> 28910.077 | ... M35: =SUMIF(CF!$E$7:$EF$7,M$3,CF!$E$173:$EF$173) -> 607424.66
A36: 기말현금 | C36: =SUMIF(CF!$E$6:$EF$6,MIN(DATE(C$3,12,31),Assumption!$E$24),CF!$E$159:$EF$159)*(C$3<=YEAR(Assumption!$E$24)) -> 2084.0179 | D36: =SUMIF(CF!$E$6:$EF$6,MIN(DATE(D$3,12,31),Assumption!$E$24),CF!$E$159:$EF$159)*(D$3<=YEAR(Assumption!$E$24)) -> 76511.599 | E36: =SUMIF(CF!$E$6:$EF$6,MIN(DATE(E$3,12,31),Assumption!$E$24),CF!$E$159:$EF$159)*(E$3<=YEAR(Assumption!$E$24)) -> 500 | F36: =SUMIF(CF!$E$6:$EF$6,MIN(DATE(F$3,12,31),Assumption!$E$24),CF!$E$159:$EF$159)*(F$3<=YEAR(Assumption!$E$24)) -> 500 | G36: =SUMIF(CF!$E$6:$EF$6,MIN(DATE(G$3,12,31),Assumption!$E$24),CF!$E$159:$EF$159)*(G$3<=YEAR(Assumption!$E$24)) -> 500 | H36: =SUMIF(CF!$E$6:$EF$6,MIN(DATE(H$3,12,31),Assumption!$E$24),CF!$E$159:$EF$159)*(H$3<=YEAR(Assumption!$E$24)) -> 288275.69 | I36: =SUMIF(CF!$E$6:$EF$6,MIN(DATE(I$3,12,31),Assumption!$E$24),CF!$E$159:$EF$159)*(I$3<=YEAR(Assumption!$E$24)) -> 471626.09 | J36: =SUMIF(CF!$E$6:$EF$6,MIN(DATE(J$3,12,31),Assumption!$E$24),CF!$E$159:$EF$159)*(J$3<=YEAR(Assumption!$E$24)) -> 484826.09 | ... M36: =SUMIF(CF!$E$6:$EF$6,MIN(DATE(M$3,12,31),Assumption!$E$24),CF!$E$159:$EF$159)*(M$3<=YEAR(Assumption!$E$24)) -> 0
A38: IRR (보통주) | B38: =CF!$C$171 -> 0.20392787
A39: IRR (우선주) | B39: =CF!$C$172 -> 0.05
A40: IRR (전체) | B40: =CF!$C$173 -> 0.12111635

Sheet Macro_VBA
A1: Run all Macro — 순환참조(금융비용·자본금) 수렴용 VBA
A3: 사용법: 1) 파일을 .xlsm으로 다른 이름 저장 2) Alt+F11 → 삽입 → 모듈 3) 아래 코드 붙여넣기 4) Alt+F8 → RunAllMacro 실행
A4: (Assumption 시트의 Macro 표: Copy 열 값을 Paste 열로 반복 복사하여 Difference가 0이 될 때까지 수렴)
A5: 가정을 바꾼 뒤 Assumption 상단 Macro Check가 "Run Macro"로 바뀌면 실행하세요.
A7: Sub RunAllMacro()
A8: Dim i As Integer
A9: Application.ScreenUpdating = False
A10: For i = 1 To 50
A11: Application.Calculate
A12: Range("Paste_Range").Value = Range("Copy_Range").Value
A13: Application.Calculate
A14: If Application.WorksheetFunction.SumProduct(Application.Evaluate("ABS(Diff_Range)")) < 0.001 Then Exit For
... A18: End Sub
